2016-04-17 15:46:20 [boto] ERROR: Caught exception reading instance data
Traceback (most recent call last):
  File "/usr/local/lib/python2.7/dist-packages/boto/utils.py", line 210, in retry_url
    r = opener.open(req, timeout=timeout)
  File "/usr/lib/python2.7/urllib2.py", line 404, in open
    response = self._open(req, data)
  File "/usr/lib/python2.7/urllib2.py", line 422, in _open
    '_open', req)
  File "/usr/lib/python2.7/urllib2.py", line 382, in _call_chain
    result = func(*args)
  File "/usr/lib/python2.7/urllib2.py", line 1214, in http_open
    return self.do_open(httplib.HTTPConnection, req)
  File "/usr/lib/python2.7/urllib2.py", line 1184, in do_open
    raise URLError(err)
URLError: <urlopen error [Errno 111] Connection refused>
2016-04-17 15:46:20 [boto] ERROR: Unable to read instance data, giving up
2016-04-17 15:50:20 [boto] ERROR: Caught exception reading instance data
Traceback (most recent call last):
  File "/usr/local/lib/python2.7/dist-packages/boto/utils.py", line 210, in retry_url
    r = opener.open(req, timeout=timeout)
  File "/usr/lib/python2.7/urllib2.py", line 404, in open
    response = self._open(req, data)
  File "/usr/lib/python2.7/urllib2.py", line 422, in _open
    '_open', req)
  File "/usr/lib/python2.7/urllib2.py", line 382, in _call_chain
    result = func(*args)
  File "/usr/lib/python2.7/urllib2.py", line 1214, in http_open
    return self.do_open(httplib.HTTPConnection, req)
  File "/usr/lib/python2.7/urllib2.py", line 1184, in do_open
    raise URLError(err)
URLError: <urlopen error [Errno 111] Connection refused>
2016-04-17 15:50:20 [boto] ERROR: Unable to read instance data, giving up
2016-04-17 15:58:22 [boto] ERROR: Caught exception reading instance data
Traceback (most recent call last):
  File "/usr/local/lib/python2.7/dist-packages/boto/utils.py", line 210, in retry_url
    r = opener.open(req, timeout=timeout)
  File "/usr/lib/python2.7/urllib2.py", line 404, in open
    response = self._open(req, data)
  File "/usr/lib/python2.7/urllib2.py", line 422, in _open
    '_open', req)
  File "/usr/lib/python2.7/urllib2.py", line 382, in _call_chain
    result = func(*args)
  File "/usr/lib/python2.7/urllib2.py", line 1214, in http_open
    return self.do_open(httplib.HTTPConnection, req)
  File "/usr/lib/python2.7/urllib2.py", line 1184, in do_open
    raise URLError(err)
URLError: <urlopen error [Errno 111] Connection refused>
2016-04-17 15:58:22 [boto] ERROR: Unable to read instance data, giving up
2016-04-17 15:59:43 [scrapy] ERROR: Unable to send mail: To=['annajo1138@gmail.com'] Cc=None Subject="Scrapy stats for: tvtropes" Attachs=0- Connection was refused by other side: 111: Connection refused.
2016-04-17 16:00:22 [boto] ERROR: Caught exception reading instance data
Traceback (most recent call last):
  File "/usr/local/lib/python2.7/dist-packages/boto/utils.py", line 210, in retry_url
    r = opener.open(req, timeout=timeout)
  File "/usr/lib/python2.7/urllib2.py", line 404, in open
    response = self._open(req, data)
  File "/usr/lib/python2.7/urllib2.py", line 422, in _open
    '_open', req)
  File "/usr/lib/python2.7/urllib2.py", line 382, in _call_chain
    result = func(*args)
  File "/usr/lib/python2.7/urllib2.py", line 1214, in http_open
    return self.do_open(httplib.HTTPConnection, req)
  File "/usr/lib/python2.7/urllib2.py", line 1184, in do_open
    raise URLError(err)
URLError: <urlopen error [Errno 111] Connection refused>
2016-04-17 16:00:22 [boto] ERROR: Unable to read instance data, giving up
2016-04-17 16:01:30 [scrapy] ERROR: Unable to send mail: To=['annajo1138@gmail.com'] Cc=None Subject="Scrapy stats for: tvtropes" Attachs=0- Connection was refused by other side: 111: Connection refused.
